<?xml version="1.0"?>

<robot name="Pendulum">
  <link name="base_link">
    <visual>
      <geometry>
         <box size=".2 .2 .2" />
      </geometry>
      <material name="green">
           <color rgba="0 1 0 1" />
      </material>
    </visual>
  </link>

  <link name="pendulum">
    <inertial>
      <origin xyz="0 0 -.5" rpy="0 0 0" />
      <mass value="1" />
      <inertia ixx="1" ixy="0" ixz="0" iyy="0.083" iyz="0" izz="1" />
    </inertial>
    <visual>
      <origin xyz="0 0 -.5" rpy="0 0 0" />
      <geometry>
         <cylinder length="1.1" radius=".05" />
      </geometry>
      <material name="red">
           <color rgba="1 0 0 1" />
      </material>
    </visual>
  </link>

  <joint name="joint" type="continuous">
    <parent link="base_link" />
    <child link="pendulum" />
    <origin xyz="0 0 0" />
    <axis xyz="0 1 0" />
    <limit effort="4.4"/>
  </joint>
</robot>
